Workbook

Sheet Sheet1
B1: ='[1]تقرير فرعي D_A Description'!K3 -> 0 | C1: ='[1]تقرير فرعي D_A Description'!E3 -> 0 | D1: ='[1]تقرير فرعي D_A Description'!F3 -> 0 | E1: ='[1]تقرير فرعي D_A Description'!C3 -> 0 | F1: ='[1]تقرير فرعي D_A Description'!J3 -> 0 | G1: ='[1]تقرير فرعي D_A Description'!G3 -> 0 | H1: ='[1]تقرير فرعي D_A Description'!H3 -> 0 | I1: ='[1]تقرير فرعي D_A Description'!B3 -> 0
B2: ='[1]تقرير فرعي D_A Description'!K4 -> DFSU 776355.9 | C2: ='[1]تقرير فرعي D_A Description'!E4 -> 237629895 | D2: ='[1]تقرير فرعي D_A Description'!F4 -> شركة السيار للتوكيلات الملاحية | E2: ='[1]تقرير فرعي D_A Description'!C4 -> 1 | F2: ='[1]تقرير فرعي D_A Description'!J4 -> 40HQ | G2: ='[1]تقرير فرعي D_A Description'!G4 -> 86 | H2: ='[1]تقرير فرعي D_A Description'!H4 -> 6350 | I2: ='[1]تقرير فرعي D_A Description'!B4 -> 523917-562395-256839
B3: ='[1]تقرير فرعي D_A Description'!K8 -> CIPU 503525.0 | C3: ='[1]تقرير فرعي D_A Description'!E8 -> 237629934 | D3: ='[1]تقرير فرعي D_A Description'!F8 -> شركة السيار للتوكيلات الملاحية | E3: ='[1]تقرير فرعي D_A Description'!C8 -> 1 | F3: ='[1]تقرير فرعي D_A Description'!J8 -> 40HQ | G3: ='[1]تقرير فرعي D_A Description'!G8 -> 86 | H3: ='[1]تقرير فرعي D_A Description'!H8 -> 6450 | I3: ='[1]تقرير فرعي D_A Description'!B8 -> 475431-568226-355893
B4: ='[1]تقرير فرعي D_A Description'!K12 -> TCKU 723114.7 | C4: ='[1]تقرير فرعي D_A Description'!E12 -> 237629948 | D4: ='[1]تقرير فرعي D_A Description'!F12 -> شركة السيار للتوكيلات الملاحية | E4: ='[1]تقرير فرعي D_A Description'!C12 -> 1 | F4: ='[1]تقرير فرعي D_A Description'!J12 -> 40HQ | G4: ='[1]تقرير فرعي D_A Description'!G12 -> 86 | H4: ='[1]تقرير فرعي D_A Description'!H12 -> 6350 | I4: ='[1]تقرير فرعي D_A Description'!B12 -> 060074-011256-693540
B5: ='[1]تقرير فرعي D_A Description'!K16 -> MRKU 585941.4 | C5: ='[1]تقرير فرعي D_A Description'!E16 -> 237629978 | D5: ='[1]تقرير فرعي D_A Description'!F16 -> شركة السيار للتوكيلات الملاحية | E5: ='[1]تقرير فرعي D_A Description'!C16 -> 1 | F5: ='[1]تقرير فرعي D_A Description'!J16 -> 40HQ | G5: ='[1]تقرير فرعي D_A Description'!G16 -> 86 | H5: ='[1]تقرير فرعي D_A Description'!H16 -> 6450 | I5: ='[1]تقرير فرعي D_A Description'!B16 -> 489477-482833-296984
B6: ='[1]تقرير فرعي D_A Description'!K20 -> TCNU 549653.7 | C6: ='[1]تقرير فرعي D_A Description'!E20 -> 237740105 | D6: ='[1]تقرير فرعي D_A Description'!F20 -> شركة السيار للتوكيلات الملاحية | E6: ='[1]تقرير فرعي D_A Description'!C20 -> 1 | F6: ='[1]تقرير فرعي D_A Description'!J20 -> 40HQ | G6: ='[1]تقرير فرعي D_A Description'!G20 -> 86 | H6: ='[1]تقرير فرعي D_A Description'!H20 -> 6350 | I6: ='[1]تقرير فرعي D_A Description'!B20 -> 276034-496657-268046
B7: ='[1]تقرير فرعي D_A Description'!K24 -> MRKU 498664.6 | C7: ='[1]تقرير فرعي D_A Description'!E24 -> 237740149 | D7: ='[1]تقرير فرعي D_A Description'!F24 -> شركة السيار للتوكيلات الملاحية | E7: ='[1]تقرير فرعي D_A Description'!C24 -> 1 | F7: ='[1]تقرير فرعي D_A Description'!J24 -> 40HQ | G7: ='[1]تقرير فرعي D_A Description'!G24 -> 86 | H7: ='[1]تقرير فرعي D_A Description'!H24 -> 6250 | I7: ='[1]تقرير فرعي D_A Description'!B24 -> 329522-263849-827499
B8: ='[1]تقرير فرعي D_A Description'!K28 -> PONU 762614.1 | C8: ='[1]تقرير فرعي D_A Description'!E28 -> 237740176 | D8: ='[1]تقرير فرعي D_A Description'!F28 -> شركة السيار للتوكيلات الملاحية | E8: ='[1]تقرير فرعي D_A Description'!C28 -> 1 | F8: ='[1]تقرير فرعي D_A Description'!J28 -> 40HQ | G8: ='[1]تقرير فرعي D_A Description'!G28 -> 86 | H8: ='[1]تقرير فرعي D_A Description'!H28 -> 6250 | I8: ='[1]تقرير فرعي D_A Description'!B28 -> 079894-515631-201658
B9: ='[1]تقرير فرعي D_A Description'!K32 -> PONU 826560.8 | C9: ='[1]تقرير فرعي D_A Description'!E32 -> 237740207 | D9: ='[1]تقرير فرعي D_A Description'!F32 -> شركة السيار للتوكيلات الملاحية | E9: ='[1]تقرير فرعي D_A Description'!C32 -> 1 | F9: ='[1]تقرير فرعي D_A Description'!J32 -> 40HQ | G9: ='[1]تقرير فرعي D_A Description'!G32 -> 86 | H9: ='[1]تقرير فرعي D_A Description'!H32 -> 6450 | I9: ='[1]تقرير فرعي D_A Description'!B32 -> 569156-848557-463850
B10: ='[1]تقرير فرعي D_A Description'!K36 -> MRSU 508506.0 | C10: ='[1]تقرير فرعي D_A Description'!E36 -> 237740244 | D10: ='[1]تقرير فرعي D_A Description'!F36 -> شركة السيار للتوكيلات الملاحية | E10: ='[1]تقرير فرعي D_A Description'!C36 -> 1 | F10: ='[1]تقرير فرعي D_A Description'!J36 -> 40HQ | G10: ='[1]تقرير فرعي D_A Description'!G36 -> 86 | H10: ='[1]تقرير فرعي D_A Description'!H36 -> 6450 | I10: ='[1]تقرير فرعي D_A Description'!B36 -> 0229604-51529-002493
B11: ='[1]تقرير فرعي D_A Description'!K40 -> HASU 509288.1 | C11: ='[1]تقرير فرعي D_A Description'!E40 -> 238148207 | D11: ='[1]تقرير فرعي D_A Description'!F40 -> شركة السيار للتوكيلات الملاحية | E11: ='[1]تقرير فرعي D_A Description'!C40 -> 5 | F11: ='[1]تقرير فرعي D_A Description'!J40 -> 40HQ | G11: ='[1]تقرير فرعي D_A Description'!G40 -> 86 | H11: ='[1]تقرير فرعي D_A Description'!H40 -> 6870 | I11: ='[1]تقرير فرعي D_A Description'!B40 -> 5TFUY5F15BX205346-218048-506639
B12: ='[1]تقرير فرعي D_A Description'!K41 -> CAAU 563466.6 | C12: ='[1]تقرير فرعي D_A Description'!E41 -> 238148207 | D12: ='[1]تقرير فرعي D_A Description'!F41 -> شركة السيار للتوكيلات الملاحية | E12: ='[1]تقرير فرعي D_A Description'!C41 -> 5 | F12: ='[1]تقرير فرعي D_A Description'!J41 -> 40HQ | G12: ='[1]تقرير فرعي D_A Description'!G41 -> 86 | H12: ='[1]تقرير فرعي D_A Description'!H41 -> 6870 | I12: ='[1]تقرير فرعي D_A Description'!B41 -> 424181-007610-727813
B13: ='[1]تقرير فرعي D_A Description'!K42 -> TCNU 876679.1 | C13: ='[1]تقرير فرعي D_A Description'!E42 -> 238148207 | D13: ='[1]تقرير فرعي D_A Description'!F42 -> شركة السيار للتوكيلات الملاحية | E13: ='[1]تقرير فرعي D_A Description'!C42 -> 5 | F13: ='[1]تقرير فرعي D_A Description'!J42 -> 40HQ | G13: ='[1]تقرير فرعي D_A Description'!G42 -> 86 | H13: ='[1]تقرير فرعي D_A Description'!H42 -> 6870 | I13: ='[1]تقرير فرعي D_A Description'!B42 -> 224735-399840-378110-173148
B14: ='[1]تقرير فرعي D_A Description'!K43 -> MRKU 414499.3 | C14: ='[1]تقرير فرعي D_A Description'!E43 -> 238148207 | D14: ='[1]تقرير فرعي D_A Description'!F43 -> شركة السيار للتوكيلات الملاحية | E14: ='[1]تقرير فرعي D_A Description'!C43 -> 5 | F14: ='[1]تقرير فرعي D_A Description'!J43 -> 40HQ | G14: ='[1]تقرير فرعي D_A Description'!G43 -> 86 | H14: ='[1]تقرير فرعي D_A Description'!H43 -> 6870 | I14: ='[1]تقرير فرعي D_A Description'!B43 -> 441216-016089-809887-118683
B15: ='[1]تقرير فرعي D_A Description'!K44 -> HASU 454917.1 | C15: ='[1]تقرير فرعي D_A Description'!E44 -> 238148207 | D15: ='[1]تقرير فرعي D_A Description'!F44 -> شركة السيار للتوكيلات الملاحية | E15: ='[1]تقرير فرعي D_A Description'!C44 -> 5 | F15: ='[1]تقرير فرعي D_A Description'!J44 -> 40HQ | G15: ='[1]تقرير فرعي D_A Description'!G44 -> 86 | H15: ='[1]تقرير فرعي D_A Description'!H44 -> 6870 | I15: ='[1]تقرير فرعي D_A Description'!B44 -> 098240-077271-276763
B16: ='[1]تقرير فرعي D_A Description'!K66 -> MRSU 613216.6 | C16: ='[1]تقرير فرعي D_A Description'!E66 -> 238152130 | D16: ='[1]تقرير فرعي D_A Description'!F66 -> شركة السيار للتوكيلات الملاحية | E16: ='[1]تقرير فرعي D_A Description'!C66 -> 1 | F16: ='[1]تقرير فرعي D_A Description'!J66 -> 40HQ | G16: ='[1]تقرير فرعي D_A Description'!G66 -> 86 | H16: ='[1]تقرير فرعي D_A Description'!H66 -> 6450 | I16: ='[1]تقرير فرعي D_A Description'!B66 -> 127372-540893-264407
B17: ='[1]تقرير فرعي D_A Description'!K70 -> TGBU 535936.5 | C17: ='[1]تقرير فرعي D_A Description'!E70 -> 238152189 | D17: ='[1]تقرير فرعي D_A Description'!F70 -> شركة السيار للتوكيلات الملاحية | E17: ='[1]تقرير فرعي D_A Description'!C70 -> 1 | F17: ='[1]تقرير فرعي D_A Description'!J70 -> 40HQ | G17: ='[1]تقرير فرعي D_A Description'!G70 -> 86 | H17: ='[1]تقرير فرعي D_A Description'!H70 -> 6450 | I17: ='[1]تقرير فرعي D_A Description'!B70 -> 123526-412418-273706
B18: ='[1]تقرير فرعي D_A Description'!K74 -> TCLU 797823.2 | C18: ='[1]تقرير فرعي D_A Description'!E74 -> 238152210 | D18: ='[1]تقرير فرعي D_A Description'!F74 -> شركة السيار للتوكيلات الملاحية | E18: ='[1]تقرير فرعي D_A Description'!C74 -> 1 | F18: ='[1]تقرير فرعي D_A Description'!J74 -> 40HQ | G18: ='[1]تقرير فرعي D_A Description'!G74 -> 86 | H18: ='[1]تقرير فرعي D_A Description'!H74 -> 6350 | I18: ='[1]تقرير فرعي D_A Description'!B74 -> 007256-154867-803531
B19: ='[1]تقرير فرعي D_A Description'!K78 -> MRKU 401919.0 | C19: ='[1]تقرير فرعي D_A Description'!E78 -> 238152220 | D19: ='[1]تقرير فرعي D_A Description'!F78 -> شركة السيار للتوكيلات الملاحية | E19: ='[1]تقرير فرعي D_A Description'!C78 -> 1 | F19: ='[1]تقرير فرعي D_A Description'!J78 -> 40HQ | G19: ='[1]تقرير فرعي D_A Description'!G78 -> 86 | H19: ='[1]تقرير فرعي D_A Description'!H78 -> 6450 | I19: ='[1]تقرير فرعي D_A Description'!B78 -> 234150-028526-045281
B20: ='[1]تقرير فرعي D_A Description'!K82 -> MRSU 341962.0 | C20: ='[1]تقرير فرعي D_A Description'!E82 -> 238152225 | D20: ='[1]تقرير فرعي D_A Description'!F82 -> شركة السيار للتوكيلات الملاحية | E20: ='[1]تقرير فرعي D_A Description'!C82 -> 1 | F20: ='[1]تقرير فرعي D_A Description'!J82 -> 40HQ | G20: ='[1]تقرير فرعي D_A Description'!G82 -> 86 | H20: ='[1]تقرير فرعي D_A Description'!H82 -> 6450 | I20: ='[1]تقرير فرعي D_A Description'!B82 -> 219994-213436-214479
B21: ='[1]تقرير فرعي D_A Description'!K86 -> WCIU 991317.9 | C21: ='[1]تقرير فرعي D_A Description'!E86 -> 238152242 | D21: ='[1]تقرير فرعي D_A Description'!F86 -> شركة السيار للتوكيلات الملاحية | E21: ='[1]تقرير فرعي D_A Description'!C86 -> 1 | F21: ='[1]تقرير فرعي D_A Description'!J86 -> 40HQ | G21: ='[1]تقرير فرعي D_A Description'!G86 -> 86 | H21: ='[1]تقرير فرعي D_A Description'!H86 -> 6350 | I21: ='[1]تقرير فرعي D_A Description'!B86 -> 229497-448647-300700
B22: ='[1]تقرير فرعي D_A Description'!K90 -> MRSU 649292.2 | C22: ='[1]تقرير فرعي D_A Description'!E90 -> 238152253 | D22: ='[1]تقرير فرعي D_A Description'!F90 -> شركة السيار للتوكيلات الملاحية | E22: ='[1]تقرير فرعي D_A Description'!C90 -> 1 | F22: ='[1]تقرير فرعي D_A Description'!J90 -> 40HQ | G22: ='[1]تقرير فرعي D_A Description'!G90 -> 86 | H22: ='[1]تقرير فرعي D_A Description'!H90 -> 6450 | I22: ='[1]تقرير فرعي D_A Description'!B90 -> 119731-095330-951805
B23: ='[1]تقرير فرعي D_A Description'!K94 -> HASU 495031.1 | C23: ='[1]تقرير فرعي D_A Description'!E94 -> 238152261 | D23: ='[1]تقرير فرعي D_A Description'!F94 -> شركة السيار للتوكيلات الملاحية | E23: ='[1]تقرير فرعي D_A Description'!C94 -> 1 | F23: ='[1]تقرير فرعي D_A Description'!J94 -> 40HQ | G23: ='[1]تقرير فرعي D_A Description'!G94 -> 86 | H23: ='[1]تقرير فرعي D_A Description'!H94 -> 6450 | I23: ='[1]تقرير فرعي D_A Description'!B94 -> 027275-060422-225769
B24: ='[1]تقرير فرعي D_A Description'!K98 -> HASU 511594.5 | C24: ='[1]تقرير فرعي D_A Description'!E98 -> 238266346 | D24: ='[1]تقرير فرعي D_A Description'!F98 -> شركة السيار للتوكيلات الملاحية | E24: ='[1]تقرير فرعي D_A Description'!C98 -> 5 | F24: ='[1]تقرير فرعي D_A Description'!J98 -> 40HQ | G24: 86 | H24: 6140 | I24: ='[1]تقرير فرعي D_A Description'!B98 -> 010537-069463-007081-
B25: ='[1]تقرير فرعي D_A Description'!K99 -> AMFU 878443.2 | C25: ='[1]تقرير فرعي D_A Description'!E99 -> 0 | D25: ='[1]تقرير فرعي D_A Description'!F99 -> 0 | E25: ='[1]تقرير فرعي D_A Description'!C99 -> 0 | F25: ='[1]تقرير فرعي D_A Description'!J99 -> 40HQ | G25: 86 | H25: 6140 | I25: ='[1]تقرير فرعي D_A Description'!B99 -> 128435-090887-170325
B26: ='[1]تقرير فرعي D_A Description'!K100 -> SUDU 852978.8 | C26: ='[1]تقرير فرعي D_A Description'!E100 -> 0 | D26: ='[1]تقرير فرعي D_A Description'!F100 -> 0 | E26: ='[1]تقرير فرعي D_A Description'!C100 -> 0 | F26: ='[1]تقرير فرعي D_A Description'!J100 -> 40HQ | G26: 86 | H26: 6140 | I26: ='[1]تقرير فرعي D_A Description'!B100 -> 273562-506022-544398
B27: ='[1]تقرير فرعي D_A Description'!K101 -> MRSU 485987.6 | C27: ='[1]تقرير فرعي D_A Description'!E101 -> 0 | D27: ='[1]تقرير فرعي D_A Description'!F101 -> 0 | E27: ='[1]تقرير فرعي D_A Description'!C101 -> 0 | F27: ='[1]تقرير فرعي D_A Description'!J101 -> 40HQ | G27: 86 | H27: 6140 | I27: ='[1]تقرير فرعي D_A Description'!B101 -> 207390-641221-088294
B28: ='[1]تقرير فرعي D_A Description'!K102 -> MSKU 146866.6 | C28: ='[1]تقرير فرعي D_A Description'!E102 -> 0 | D28: ='[1]تقرير فرعي D_A Description'!F102 -> 0 | E28: ='[1]تقرير فرعي D_A Description'!C102 -> 0 | F28: ='[1]تقرير فرعي D_A Description'!J102 -> 40HQ | G28: ='[1]تقرير فرعي D_A Description'!G102 -> 0 | H28: ='[1]تقرير فرعي D_A Description'!H102 -> 0 | I28: ='[1]تقرير فرعي D_A Description'!B102 -> 018033-141708-823301
B29: ='[1]تقرير فرعي D_A Description'!K122 -> TCKU 738791.0 | C29: ='[1]تقرير فرعي D_A Description'!E122 -> 238266368 | D29: ='[1]تقرير فرعي D_A Description'!F122 -> شركة السيار للتوكيلات الملاحية | E29: ='[1]تقرير فرعي D_A Description'!C122 -> 5 | F29: ='[1]تقرير فرعي D_A Description'!J122 -> 40HQ | G29: 86 | H29: 7220 | I29: ='[1]تقرير فرعي D_A Description'!B122 -> 076106-219706-336496
B30: ='[1]تقرير فرعي D_A Description'!K123 -> MRKU 343627.0 | C30: ='[1]تقرير فرعي D_A Description'!E123 -> 0 | D30: ='[1]تقرير فرعي D_A Description'!F123 -> 0 | E30: ='[1]تقرير فرعي D_A Description'!C123 -> 0 | F30: ='[1]تقرير فرعي D_A Description'!J123 -> 40HQ | G30: 86 | H30: 7220 | I30: ='[1]تقرير فرعي D_A Description'!B123 -> 060946-223715-581611
B31: ='[1]تقرير فرعي D_A Description'!K124 -> MRKU 388502.9 | C31: ='[1]تقرير فرعي D_A Description'!E124 -> 0 | D31: ='[1]تقرير فرعي D_A Description'!F124 -> 0 | E31: ='[1]تقرير فرعي D_A Description'!C124 -> 0 | F31: ='[1]تقرير فرعي D_A Description'!J124 -> 40HQ | G31: 86 | H31: 7220 | I31: ='[1]تقرير فرعي D_A Description'!B124 -> 933654-287068-224668-488631
B32: ='[1]تقرير فرعي D_A Description'!K125 -> MSKU 018285.2 | C32: ='[1]تقرير فرعي D_A Description'!E125 -> 0 | D32: ='[1]تقرير فرعي D_A Description'!F125 -> 0 | E32: ='[1]تقرير فرعي D_A Description'!C125 -> 0 | F32: ='[1]تقرير فرعي D_A Description'!J125 -> 40HQ | G32: 86 | H32: 7220 | I32: ='[1]تقرير فرعي D_A Description'!B125 -> 031745-042338-189619-218959
B33: ='[1]تقرير فرعي D_A Description'!K126 -> MRSU 535123.6 | C33: ='[1]تقرير فرعي D_A Description'!E126 -> 0 | D33: ='[1]تقرير فرعي D_A Description'!F126 -> 0 | E33: ='[1]تقرير فرعي D_A Description'!C126 -> 0 | F33: ='[1]تقرير فرعي D_A Description'!J126 -> 40HQ | G33: ='[1]تقرير فرعي D_A Description'!G126 -> 0 | H33: ='[1]تقرير فرعي D_A Description'!H126 -> 0 | I33: ='[1]تقرير فرعي D_A Description'!B126 -> 106131-404989-097540-685683
B34: ='[1]تقرير فرعي D_A Description'!K149 -> MSKU 156140.2 | C34: ='[1]تقرير فرعي D_A Description'!E149 -> 238267324 | D34: ='[1]تقرير فرعي D_A Description'!F149 -> شركة السيار للتوكيلات الملاحية | E34: ='[1]تقرير فرعي D_A Description'!C149 -> 1 | F34: ='[1]تقرير فرعي D_A Description'!J149 -> 40HQ | G34: ='[1]تقرير فرعي D_A Description'!G149 -> 86 | H34: ='[1]تقرير فرعي D_A Description'!H149 -> 6850 | I34: ='[1]تقرير فرعي D_A Description'!B149 -> 370762-541364-306300
B35: ='[1]تقرير فرعي D_A Description'!K153 -> CAAU 663345.3 | C35: ='[1]تقرير فرعي D_A Description'!E153 -> 238267334 | D35: ='[1]تقرير فرعي D_A Description'!F153 -> شركة السيار للتوكيلات الملاحية | E35: ='[1]تقرير فرعي D_A Description'!C153 -> 1 | F35: ='[1]تقرير فرعي D_A Description'!J153 -> 40HQ | G35: ='[1]تقرير فرعي D_A Description'!G153 -> 86 | H35: ='[1]تقرير فرعي D_A Description'!H153 -> 6450 | I35: ='[1]تقرير فرعي D_A Description'!B153 -> 767706-057833-058486
B36: ='[1]تقرير فرعي D_A Description'!K157 -> MSKU 133761.9 | C36: ='[1]تقرير فرعي D_A Description'!E157 -> 238267344 | D36: ='[1]تقرير فرعي D_A Description'!F157 -> شركة السيار للتوكيلات الملاحية | E36: ='[1]تقرير فرعي D_A Description'!C157 -> 1 | F36: ='[1]تقرير فرعي D_A Description'!J157 -> 40HQ | G36: ='[1]تقرير فرعي D_A Description'!G157 -> 86 | H36: ='[1]تقرير فرعي D_A Description'!H157 -> 6350 | I36: ='[1]تقرير فرعي D_A Description'!B157 -> 972582-252058-103639
B37: ='[1]تقرير فرعي D_A Description'!K161 -> MRSU 490997.7 | C37: ='[1]تقرير فرعي D_A Description'!E161 -> 238267360 | D37: ='[1]تقرير فرعي D_A Description'!F161 -> شركة السيار للتوكيلات الملاحية | E37: ='[1]تقرير فرعي D_A Description'!C161 -> 1 | F37: ='[1]تقرير فرعي D_A Description'!J161 -> 40HQ | G37: ='[1]تقرير فرعي D_A Description'!G161 -> 86 | H37: ='[1]تقرير فرعي D_A Description'!H161 -> 6350 | I37: ='[1]تقرير فرعي D_A Description'!B161 -> 076675-007936-108397
B38: ='[1]تقرير فرعي D_A Description'!K165 -> MSKU 079227.0 | C38: ='[1]تقرير فرعي D_A Description'!E165 -> 238267368 | D38: ='[1]تقرير فرعي D_A Description'!F165 -> شركة السيار للتوكيلات الملاحية | E38: ='[1]تقرير فرعي D_A Description'!C165 -> 1 | F38: ='[1]تقرير فرعي D_A Description'!J165 -> 40HQ | G38: ='[1]تقرير فرعي D_A Description'!G165 -> 86 | H38: ='[1]تقرير فرعي D_A Description'!H165 -> 6250 | I38: ='[1]تقرير فرعي D_A Description'!B165 -> 491602-151961-839349
B39: ='[1]تقرير فرعي D_A Description'!K169 -> MRKU 338021.1 | C39: ='[1]تقرير فرعي D_A Description'!E169 -> 239183402 | D39: ='[1]تقرير فرعي D_A Description'!F169 -> شركة السيار للتوكيلات الملاحية | E39: ='[1]تقرير فرعي D_A Description'!C169 -> 1 | F39: ='[1]تقرير فرعي D_A Description'!J169 -> 40HQ | G39: ='[1]تقرير فرعي D_A Description'!G169 -> 86 | H39: ='[1]تقرير فرعي D_A Description'!H169 -> 6450 | I39: ='[1]تقرير فرعي D_A Description'!B169 -> 064288-923440-106229
B40: ='[1]تقرير فرعي D_A Description'!K173 -> CAAU 531532.9 | C40: ='[1]تقرير فرعي D_A Description'!E173 -> 239183412 | D40: ='[1]تقرير فرعي D_A Description'!F173 -> شركة السيار للتوكيلات الملاحية | E40: ='[1]تقرير فرعي D_A Description'!C173 -> 1 | F40: ='[1]تقرير فرعي D_A Description'!J173 -> 40HQ | G40: ='[1]تقرير فرعي D_A Description'!G173 -> 86 | H40: ='[1]تقرير فرعي D_A Description'!H173 -> 6250 | I40: ='[1]تقرير فرعي D_A Description'!B173 -> 001037-169540-166502
...

Sheet Sheet2
A1: T1 | B1: T2 | C1: T3 | D1: T7 | E1: T8 | F1: T4 | G1: T5 | H1: T6 | I1: T7 | J1: T9 | K1: T10 | L1: T11 | M1: T12 | N1: T13 | O1: T14 | P1: T15
A2: DFSU 776355.9 | B2: 237629895 | C2: شركة السيار للتوكيلات الملاحية | D2: 523917-562395-256839 | E2: 1 | F2: 40HQ | G2: 86 | H2: 6350 | I2: 523917-562395-256839
A3: CIPU 503525.0 | B3: 237629934 | C3: شركة السيار للتوكيلات الملاحية | D3: 475431-568226-355893 | E3: 1 | F3: 40HQ | G3: 86 | H3: 6450 | I3: 475431-568226-355893
A4: TCKU 723114.7 | B4: 237629948 | C4: شركة السيار للتوكيلات الملاحية | D4: 060074-011256-693540 | E4: 1 | F4: 40HQ | G4: 86 | H4: 6350 | I4: 060074-011256-693540
A5: MRKU 585941.4 | B5: 237629978 | C5: شركة السيار للتوكيلات الملاحية | D5: 489477-482833-296984 | E5: 1 | F5: 40HQ | G5: 86 | H5: 6450 | I5: 489477-482833-296984
A6: TCNU 549653.7 | B6: 237740105 | C6: شركة السيار للتوكيلات الملاحية | D6: 276034-496657-268046 | E6: 1 | F6: 40HQ | G6: 86 | H6: 6350 | I6: 276034-496657-268046
A7: MRKU 498664.6 | B7: 237740149 | C7: شركة السيار للتوكيلات الملاحية | D7: 329522-263849-827499 | E7: 1 | F7: 40HQ | G7: 86 | H7: 6250 | I7: 329522-263849-827499
A8: PONU 762614.1 | B8: 237740176 | C8: شركة السيار للتوكيلات الملاحية | D8: 079894-515631-201658 | E8: 1 | F8: 40HQ | G8: 86 | H8: 6250 | I8: 079894-515631-201658
A9: PONU 826560.8 | B9: 237740207 | C9: شركة السيار للتوكيلات الملاحية | D9: 569156-848557-463850 | E9: 1 | F9: 40HQ | G9: 86 | H9: 6450 | I9: 569156-848557-463850
A10: MRSU 508506.0 | B10: 237740244 | C10: شركة السيار للتوكيلات الملاحية | D10: 0229604-51529-002493 | E10: 1 | F10: 40HQ | G10: 86 | H10: 6450 | I10: 0229604-51529-002493
A11: HASU 509288.1 | B11: 238148207 | C11: شركة السيار للتوكيلات الملاحية | D11: 5TFUY5F15BX205346-218048-506639 | E11: 5 | F11: 40HQ | G11: 86 | H11: 6870 | I11: 5TFUY5F15BX205346-218048-506639
A12: CAAU 563466.6 | B12: 238148207 | C12: شركة السيار للتوكيلات الملاحية | D12: 424181-007610-727813 | E12: 5 | F12: 40HQ | G12: 86 | H12: 6870 | I12: 424181-007610-727813
A13: TCNU 876679.1 | B13: 238148207 | C13: شركة السيار للتوكيلات الملاحية | D13: 224735-399840-378110-173148 | E13: 5 | F13: 40HQ | G13: 86 | H13: 6870 | I13: 224735-399840-378110-173148
... A71: MRKU 232753.1 | B71: 239008179 | C71: شركة المنارة المضيئة | D71: 708913-121879-042473 | E71: 0 | F71: 40HQ | G71: 86 | H71: 6831.2 | I71: 708913-121879-042473
A72: MRSU 490535.4 | B72: 239008179 | C72: شركة المنارة المضيئة | D72: 097187-723023-099761 | E72: 0 | F72: 40HQ | G72: 86 | H72: 6831.3 | I72: 097187-723023-099761
A73: MRKU 345477.8 | B73: 239098921 | C73: شركة المنارة المضيئة | D73: 116199-238733-625231 | E73: 6 | F73: 40HQ | G73: 86 | H73: 6674.5 | I73: 116199-238733-625231
A74: MSKU 023615.7 | B74: 239098921 | C74: شركة المنارة المضيئة | D74: 209826-289587-410760-537658 | E74: 0 | F74: 40HQ | G74: 86 | H74: 6674.5 | I74: 209826-289587-410760-537658
A75: MRSU 561289.6 | B75: 239098921 | C75: شركة المنارة المضيئة | D75: 378143-733527-207028-079620 | E75: 0 | F75: 40HQ | G75: 86 | H75: 6674.5 | I75: 378143-733527-207028-079620
A76: MRSU 461984.9 | B76: 239098921 | C76: شركة المنارة المضيئة | D76: 003828-161884-140566-281108 | E76: 0 | F76: 40HQ | G76: 86 | H76: 6674.5 | I76: 003828-161884-140566-281108
A77: MRSU 327004.8 | B77: 239098921 | C77: شركة المنارة المضيئة | D77: 052042-089892-003722 | E77: 0 | F77: 40HQ | G77: 86 | H77: 6674.5 | I77: 052042-089892-003722
A78: MRKU 291424.6 | B78: 239098921 | C78: شركة المنارة المضيئة | D78: 036451-447890-478504 | E78: 0 | F78: 40HQ | G78: 86 | H78: 6674.6 | I78: 036451-447890-478504
A79: MAEU 918399.6 | B79: 239180221 | C79: شركة المنارة المضيئة | D79: 009567-651477-060981 | E79: 1 | F79: 45HQ | G79: 96 | H79: 8650 | I79: 009567-651477-060981
A80: MRKU 266922.0 | B80: 239180465 | C80: شركة المنارة المضيئة | D80: 248627-085287-031450-176749 | E80: 4 | F80: 40HQ | G80: 86 | H80: 8987.5 | I80: 248627-085287-031450-176749
A81: MSKU 102078.0 | B81: 239180465 | C81: شركة المنارة المضيئة | D81: 135401-349783-254151-610784 | E81: 0 | F81: 40HQ | G81: 86 | H81: 8987.5 | I81: 135401-349783-254151-610784
A82: TCKU 786735.5 | B82: 239180465 | C82: شركة المنارة المضيئة | D82: 019431-304908-896098-211333 | E82: 0 | F82: 40HQ | G82: 86 | H82: 8987.5 | I82: 019431-304908-896098-211333
A83: MSKU 052067.2 | B83: 239180465 | C83: شركة المنارة المضيئة | D83: 469197-265074-232234 | E83: 0 | F83: 40HQ | G83: 87 | H83: 8987.6 | I83: 469197-265074-232234
A84: HASU 414248.4 | B84: 239552335 | C84: شركة المنارة المضيئة | D84: 522562-503302-509261 | E84: 4 | F84: 40HQ | G84: 86 | H84: 8450 | I84: 522562-503302-509261
A85: MRKU 543994.1 | B85: 239552335 | C85: شركة المنارة المضيئة | D85: 372652-020570-461363 | E85: 0 | F85: 40HQ | G85: 86 | H85: 8450 | I85: 372652-020570-461363
A86: PONU 804172.1 | B86: 239552335 | C86: شركة المنارة المضيئة | D86: 111698-021449-456059 | E86: 0 | F86: 40HQ | G86: 86 | H86: 8450 | I86: 111698-021449-456059
A87: SUDU 693158.7 | B87: 239552335 | C87: شركة المنارة المضيئة | D87: 034962-455215-089856 | E87: 0 | F87: 40HQ | G87: 86 | H87: 8450 | I87: 034962-455215-089856
A88: TCLU 815828.5 | B88: 239552398 | C88: شركة المنارة المضيئة | D88: 089828-128332-268881-147644 | E88: 4 | F88: 40HQ | G88: 86 | H88: 8307.5 | I88: 089828-128332-268881-147644
A89: TRHU 519799.3 | B89: 239552398 | C89: شركة المنارة المضيئة | D89: 430987-420141-020737-282182 | E89: 0 | F89: 40HQ | G89: 86 | H89: 8307.5 | I89: 430987-420141-020737-282182
A90: FFAU 535960.8 | B90: 239552398 | C90: شركة المنارة المضيئة | D90: 612931-163595-168752 | E90: 0 | F90: 40HQ | G90: 86 | H90: 8307.5 | I90: 612931-163595-168752
... A188: MRKU 707874.5 | B188: 240448827 | C188: شركة يمامة الشرق | D188: عدد 77800 كرتونة مشروب سيرين فلوتس | E188: 0 | F188: 20DC | G188: 38.5 | H188: 19644.5 | I188: 0
A189: MSKU 737845.1 | B189: 240448827 | C189: شركة يمامة الشرق | D189: عدد 77800 كرتونة مشروب سيرين فلوتس | E189: 0 | F189: 20DC | G189: 38.5 | H189: 19644.6 | I189: 0
A190: SUDU 788778.7 | B190: 238672636 | C190: شركة العابرات الليبية للتوكيلات الملاحية والنقل | D190: عدد 3008 طرد حزم صفائح فولاذية+بخاخات+أسلاك كهربائية+ طوب+بضائع متنوعة +لفة خرطوم مياه +مجرفة+ شمسي+ اونستي+ ويلبارو+ كوتي+ مولدات+ طزينة دلو+ مواد بناء متنوعة | E190: 2 | F190: 20DC | G190: 38.5 | H190: 27590 | I190: عدد 3008 طرد حزم صفائح فولاذية+بخاخات+أسلاك كهربائية+ طوب+بضائع متنوعة +لفة خرطوم مياه +مجرفة+ شمسي+ اونستي+ ويلبارو+ كوتي+ مولدات+ طزينة دلو+ مواد بناء متنوعة
A191: CAAU 607086.9 | B191: 238672636 | C191: شركة العابرات الليبية للتوكيلات الملاحية والنقل | D191: عدد 3008 طرد حزم صفائح فولاذية+بخاخات+أسلاك كهربائية+ طوب+بضائع متنوعة +لفة خرطوم مياه +مجرفة+ شمسي+ اونستي+ ويلبارو+ كوتي+ مولدات+ طزينة دلو+ مواد بناء متنوعة | E191: 0 | F191: 40HQ | G191: 86 | H191: 27591 | I191: 0
A192: MSKU 438417.3 | B192: 239147715 | C192: شركة العابرات الليبية للتوكيلات الملاحية والنقل | D192: عدد 2250 طرد حفظ+ كيس نايلز+جاكامارا+صندوق المولد+ صفائح فولاذية+ بطانيات+تشانتا+سلع متنوعة+طوب+ إطارات+اسلاك كهربائية+كوندا+سجاد+بخاخ +ورق رام+لفة خرطوم مياه | E192: 4 | F192: 20DC | G192: 38.5 | H192: 28052.5 | I192: عدد 2250 طرد حفظ+ كيس نايلز+جاكامارا+صندوق المولد+ صفائح فولاذية+ بطانيات+تشانتا+سلع متنوعة+طوب+ إطارات+اسلاك كهربائية+كوندا+سجاد+بخاخ +ورق رام+لفة خرطوم مياه
A193: SUDU 133818.3 | B193: 239147715 | C193: شركة العابرات الليبية للتوكيلات الملاحية والنقل | D193: عدد 2250 طرد حفظ+ كيس نايلز+جاكامارا+صندوق المولد+ صفائح فولاذية+ بطانيات+تشانتا+سلع متنوعة+طوب+ إطارات+اسلاك كهربائية+كوندا+سجاد+بخاخ +ورق رام+لفة خرطوم مياه | E193: 0 | F193: 20DC | G193: 86 | H193: 28052.5 | I193: 0
A194: MRSU 423759.5 | B194: 239147715 | C194: شركة العابرات الليبية للتوكيلات الملاحية والنقل | D194: عدد 2250 طرد حفظ+ كيس نايلز+جاكامارا+صندوق المولد+ صفائح فولاذية+ بطانيات+تشانتا+سلع متنوعة+طوب+ إطارات+اسلاك كهربائية+كوندا+سجاد+بخاخ +ورق رام+لفة خرطوم مياه | E194: 0 | F194: 40HQ | G194: 86 | H194: 28052.5 | I194: 0
...

Sheet Sheet3
A1: رقم البوليصة | B1: المستلم | C1: وصف البضاعة | D1: رقم الحاوية | E1: الوزن | F1: حجم الحاوية | G1: حجم حجم البضاعة | H1: التبريد | I1: مشتركة | J1: نوع الشحنة ووصفها
A2: =Sheet2!B2 -> 237629895 | B2: =Sheet2!C2 -> شركة السيار للتوكيلات الملاحية | C2: =Sheet2!D2 -> 523917-562395-256839 | D2: =Sheet2!A2 -> DFSU 776355.9 | E2: =Sheet2!H2 -> 6350 | F2: =Sheet2!G2 -> 86 | J2: سيارات
A3: =Sheet2!B3 -> 237629934 | B3: =Sheet2!C3 -> شركة السيار للتوكيلات الملاحية | C3: =Sheet2!D3 -> 475431-568226-355893 | D3: =Sheet2!A3 -> CIPU 503525.0 | E3: =Sheet2!H3 -> 6450 | F3: =Sheet2!G3 -> 86 | J3: سيارات
A4: =Sheet2!B4 -> 237629948 | B4: =Sheet2!C4 -> شركة السيار للتوكيلات الملاحية | C4: =Sheet2!D4 -> 060074-011256-693540 | D4: =Sheet2!A4 -> TCKU 723114.7 | E4: =Sheet2!H4 -> 6350 | F4: =Sheet2!G4 -> 86 | J4: سيارات
A5: =Sheet2!B5 -> 237629978 | B5: =Sheet2!C5 -> شركة السيار للتوكيلات الملاحية | C5: =Sheet2!D5 -> 489477-482833-296984 | D5: =Sheet2!A5 -> MRKU 585941.4 | E5: =Sheet2!H5 -> 6450 | F5: =Sheet2!G5 -> 86 | J5: سيارات
A6: =Sheet2!B6 -> 237740105 | B6: =Sheet2!C6 -> شركة السيار للتوكيلات الملاحية | C6: =Sheet2!D6 -> 276034-496657-268046 | D6: =Sheet2!A6 -> TCNU 549653.7 | E6: =Sheet2!H6 -> 6350 | F6: =Sheet2!G6 -> 86 | J6: سيارات
A7: =Sheet2!B7 -> 237740149 | B7: =Sheet2!C7 -> شركة السيار للتوكيلات الملاحية | C7: =Sheet2!D7 -> 329522-263849-827499 | D7: =Sheet2!A7 -> MRKU 498664.6 | E7: =Sheet2!H7 -> 6250 | F7: =Sheet2!G7 -> 86 | J7: سيارات
A8: =Sheet2!B8 -> 237740176 | B8: =Sheet2!C8 -> شركة السيار للتوكيلات الملاحية | C8: =Sheet2!D8 -> 079894-515631-201658 | D8: =Sheet2!A8 -> PONU 762614.1 | E8: =Sheet2!H8 -> 6250 | F8: =Sheet2!G8 -> 86 | J8: سيارات
A9: =Sheet2!B9 -> 237740207 | B9: =Sheet2!C9 -> شركة السيار للتوكيلات الملاحية | C9: =Sheet2!D9 -> 569156-848557-463850 | D9: =Sheet2!A9 -> PONU 826560.8 | E9: =Sheet2!H9 -> 6450 | F9: =Sheet2!G9 -> 86 | J9: سيارات
A10: =Sheet2!B10 -> 237740244 | B10: =Sheet2!C10 -> شركة السيار للتوكيلات الملاحية | C10: =Sheet2!D10 -> 0229604-51529-002493 | D10: =Sheet2!A10 -> MRSU 508506.0 | E10: =Sheet2!H10 -> 6450 | F10: =Sheet2!G10 -> 86 | J10: سيارات
A11: =Sheet2!B11 -> 238148207 | B11: =Sheet2!C11 -> شركة السيار للتوكيلات الملاحية | C11: =Sheet2!D11 -> 5TFUY5F15BX205346-218048-506639 | D11: =Sheet2!A11 -> HASU 509288.1 | E11: =Sheet2!H11 -> 6870 | F11: =Sheet2!G11 -> 86 | J11: سيارات
A12: =Sheet2!B12 -> 238148207 | B12: =Sheet2!C12 -> شركة السيار للتوكيلات الملاحية | C12: =Sheet2!D12 -> 424181-007610-727813 | D12: =Sheet2!A12 -> CAAU 563466.6 | E12: =Sheet2!H12 -> 6870 | F12: =Sheet2!G12 -> 86 | J12: سيارات
A13: =Sheet2!B13 -> 238148207 | B13: =Sheet2!C13 -> شركة السيار للتوكيلات الملاحية | C13: =Sheet2!D13 -> 224735-399840-378110-173148 | D13: =Sheet2!A13 -> TCNU 876679.1 | E13: =Sheet2!H13 -> 6870 | F13: =Sheet2!G13 -> 86 | J13: سيارات
... A82: =Sheet2!B82 -> 239180465 | B82: =Sheet2!C82 -> شركة المنارة المضيئة | C82: =Sheet2!D82 -> 019431-304908-896098-211333 | D82: =Sheet2!A82 -> TCKU 786735.5 | E82: =Sheet2!H82 -> 8987.5 | F82: =Sheet2!G82 -> 86 | J82: سيارات
A83: =Sheet2!B83 -> 239180465 | B83: =Sheet2!C83 -> شركة المنارة المضيئة | C83: =Sheet2!D83 -> 469197-265074-232234 | D83: =Sheet2!A83 -> MSKU 052067.2 | E83: =Sheet2!H83 -> 8987.6 | F83: 86 | J83: سيارات
A84: =Sheet2!B84 -> 239552335 | B84: =Sheet2!C84 -> شركة المنارة المضيئة | C84: =Sheet2!D84 -> 522562-503302-509261 | D84: =Sheet2!A84 -> HASU 414248.4 | E84: =Sheet2!H84 -> 8450 | F84: =Sheet2!G84 -> 86 | J84: سيارات
A85: =Sheet2!B85 -> 239552335 | B85: =Sheet2!C85 -> شركة المنارة المضيئة | C85: =Sheet2!D85 -> 372652-020570-461363 | D85: =Sheet2!A85 -> MRKU 543994.1 | E85: =Sheet2!H85 -> 8450 | F85: =Sheet2!G85 -> 86 | J85: سيارات
A86: =Sheet2!B86 -> 239552335 | B86: =Sheet2!C86 -> شركة المنارة المضيئة | C86: =Sheet2!D86 -> 111698-021449-456059 | D86: =Sheet2!A86 -> PONU 804172.1 | E86: =Sheet2!H86 -> 8450 | F86: =Sheet2!G86 -> 86 | J86: سيارات
A87: =Sheet2!B87 -> 239552335 | B87: =Sheet2!C87 -> شركة المنارة المضيئة | C87: =Sheet2!D87 -> 034962-455215-089856 | D87: =Sheet2!A87 -> SUDU 693158.7 | E87: =Sheet2!H87 -> 8450 | F87: =Sheet2!G87 -> 86 | J87: سيارات
A88: =Sheet2!B88 -> 239552398 | B88: =Sheet2!C88 -> شركة المنارة المضيئة | C88: =Sheet2!D88 -> 089828-128332-268881-147644 | D88: =Sheet2!A88 -> TCLU 815828.5 | E88: =Sheet2!H88 -> 8307.5 | F88: =Sheet2!G88 -> 86 | J88: سيارات
A89: =Sheet2!B89 -> 239552398 | B89: =Sheet2!C89 -> شركة المنارة المضيئة | C89: =Sheet2!D89 -> 430987-420141-020737-282182 | D89: =Sheet2!A89 -> TRHU 519799.3 | E89: =Sheet2!H89 -> 8307.5 | F89: =Sheet2!G89 -> 86 | J89: سيارات
A90: =Sheet2!B90 -> 239552398 | B90: =Sheet2!C90 -> شركة المنارة المضيئة | C90: =Sheet2!D90 -> 612931-163595-168752 | D90: =Sheet2!A90 -> FFAU 535960.8 | E90: =Sheet2!H90 -> 8307.5 | F90: =Sheet2!G90 -> 86 | J90: سيارات
A91: =Sheet2!B91 -> 239552398 | B91: =Sheet2!C91 -> شركة المنارة المضيئة | C91: =Sheet2!D91 -> 256445-023944-049783-025717 | D91: =Sheet2!A91 -> MRKU 244545.2 | E91: =Sheet2!H91 -> 8307.6 | F91: 86 | J91: سيارات
A92: =Sheet2!B92 -> 239552619 | B92: =Sheet2!C92 -> شركة المنارة المضيئة | C92: =Sheet2!D92 -> 474611-523262-156435 | D92: =Sheet2!A92 -> MAEU 917716.5 | E92: =Sheet2!H92 -> 8850 | F92: =Sheet2!G92 -> 96 | J92: سيارات
A93: =Sheet2!B93 -> 238426938 | B93: =Sheet2!C93 -> شركة الريادة للتوكيلات الملاحية | C93: =Sheet2!D93 -> عدد 4506 طرد قطع غيار وكماليات سيارات +احذية+ جوارب+حقائب+الات موسيقية+فشار +أجهزة كهربائية +منتجات تنظيف+عازل سيليكون مطاطي+ الات خط إنتاج المواد الغذائية+ عدد9 سيارات(ارقام الهيكل بالكشف المرفق) | D93: =Sheet2!A93 -> TCLU 338997.5 | E93: =Sheet2!H93 -> 8233 | F93: =Sheet2!G93 -> 38.5 | J93: بضائع مختلفة
A94: =Sheet2!B94 -> 238426938 | B94: =Sheet2!C94 -> شركة الريادة للتوكيلات الملاحية | C94: =Sheet2!D94 -> عدد 4506 طرد قطع غيار وكماليات سيارات +احذية+ جوارب+حقائب+الات موسيقية+فشار +أجهزة كهربائية +منتجات تنظيف+عازل سيليكون مطاطي+ الات خط إنتاج المواد الغذائية+ عدد9 سيارات(ارقام الهيكل بالكشف المرفق) | D94: =Sheet2!A94 -> HASU 113148.6 | E94: =Sheet2!H94 -> 8233 | F94: =Sheet2!G94 -> 38.5 | J94: بضائع مختلفة
A95: =Sheet2!B95 -> 238426938 | B95: =Sheet2!C95 -> شركة الريادة للتوكيلات الملاحية | C95: =Sheet2!D95 -> عدد 4506 طرد قطع غيار وكماليات سيارات +احذية+ جوارب+حقائب+الات موسيقية+فشار +أجهزة كهربائية +منتجات تنظيف+عازل سيليكون مطاطي+ الات خط إنتاج المواد الغذائية+ عدد9 سيارات(ارقام الهيكل بالكشف المرفق) | D95: =Sheet2!A95 -> MSKU 562050.3 | E95: =Sheet2!H95 -> 8233 | F95: =Sheet2!G95 -> 38.5 | J95: بضائع مختلفة
A96: =Sheet2!B96 -> 238426938 | B96: =Sheet2!C96 -> شركة الريادة للتوكيلات الملاحية | C96: =Sheet2!D96 -> عدد 4506 طرد قطع غيار وكماليات سيارات +احذية+ جوارب+حقائب+الات موسيقية+فشار +أجهزة كهربائية +منتجات تنظيف+عازل سيليكون مطاطي+ الات خط إنتاج المواد الغذائية+ عدد9 سيارات(ارقام الهيكل بالكشف المرفق) | D96: =Sheet2!A96 -> MRKU 996740.1 | E96: =Sheet2!H96 -> 8233 | F96: =Sheet2!G96 -> 86 | J96: بضائع مختلفة
A97: =Sheet2!B97 -> 238426938 | B97: =Sheet2!C97 -> شركة الريادة للتوكيلات الملاحية | C97: =Sheet2!D97 -> عدد 4506 طرد قطع غيار وكماليات سيارات +احذية+ جوارب+حقائب+الات موسيقية+فشار +أجهزة كهربائية +منتجات تنظيف+عازل سيليكون مطاطي+ الات خط إنتاج المواد الغذائية+ عدد9 سيارات(ارقام الهيكل بالكشف المرفق) | D97: =Sheet2!A97 -> MRKU 567520.6 | E97: =Sheet2!H97 -> 8233 | F97: =Sheet2!G97 -> 86 | J97: بضائع مختلفة
A98: =Sheet2!B98 -> 238426938 | B98: =Sheet2!C98 -> شركة الريادة للتوكيلات الملاحية | C98: =Sheet2!D98 -> عدد 4506 طرد قطع غيار وكماليات سيارات +احذية+ جوارب+حقائب+الات موسيقية+فشار +أجهزة كهربائية +منتجات تنظيف+عازل سيليكون مطاطي+ الات خط إنتاج المواد الغذائية+ عدد9 سيارات(ارقام الهيكل بالكشف المرفق) | D98: =Sheet2!A98 -> TCKU 612952.6 | E98: =Sheet2!H98 -> 8233 | F98: =Sheet2!G98 -> 86 | J98: بضائع مختلفة
A99: =Sheet2!B99 -> 238426938 | B99: =Sheet2!C99 -> شركة الريادة للتوكيلات الملاحية | C99: =Sheet2!D99 -> عدد 4506 طرد قطع غيار وكماليات سيارات +احذية+ جوارب+حقائب+الات موسيقية+فشار +أجهزة كهربائية +منتجات تنظيف+عازل سيليكون مطاطي+ الات خط إنتاج المواد الغذائية+ عدد9 سيارات(ارقام الهيكل بالكشف المرفق) | D99: =Sheet2!A99 -> TLLU 766146.2 | E99: =Sheet2!H99 -> 8233 | F99: =Sheet2!G99 -> 86 | J99: بضائع مختلفة
A100: =Sheet2!B100 -> 238426938 | B100: =Sheet2!C100 -> شركة الريادة للتوكيلات الملاحية | C100: =Sheet2!D100 -> عدد 4506 طرد قطع غيار وكماليات سيارات +احذية+ جوارب+حقائب+الات موسيقية+فشار +أجهزة كهربائية +منتجات تنظيف+عازل سيليكون مطاطي+ الات خط إنتاج المواد الغذائية+ عدد9 سيارات(ارقام الهيكل بالكشف المرفق) | D100: =Sheet2!A100 -> MRKU 421054.4 | E100: =Sheet2!H100 -> 8233 | F100: =Sheet2!G100 -> 86 | J100: بضائع مختلفة
A101: =Sheet2!B101 -> 238426938 | B101: =Sheet2!C101 -> شركة الريادة للتوكيلات الملاحية | C101: =Sheet2!D101 -> عدد 4506 طرد قطع غيار وكماليات سيارات +احذية+ جوارب+حقائب+الات موسيقية+فشار +أجهزة كهربائية +منتجات تنظيف+عازل سيليكون مطاطي+ الات خط إنتاج المواد الغذائية+ عدد9 سيارات(ارقام الهيكل بالكشف المرفق) | D101: =Sheet2!A101 -> MSKU 168667.3 | E101: =Sheet2!H101 -> 8233 | F101: =Sheet2!G101 -> 86 | J101: بضائع مختلفة
A102: =Sheet2!B102 -> 238426938 | B102: =Sheet2!C102 -> شركة الريادة للتوكيلات الملاحية | C102: =Sheet2!D102 -> عدد 4506 طرد قطع غيار وكماليات سيارات +احذية+ جوارب+حقائب+الات موسيقية+فشار +أجهزة كهربائية +منتجات تنظيف+عازل سيليكون مطاطي+ الات خط إنتاج المواد الغذائية+ عدد9 سيارات(ارقام الهيكل بالكشف المرفق) | D102: =Sheet2!A102 -> MRSU 573366.6 | E102: =Sheet2!H102 -> 8233 | F102: =Sheet2!G102 -> 86 | J102: بضائع مختلفة
A103: =Sheet2!B103 -> 238426938 | B103: =Sheet2!C103 -> شركة الريادة للتوكيلات الملاحية | C103: =Sheet2!D103 -> عدد 4506 طرد قطع غيار وكماليات سيارات +احذية+ جوارب+حقائب+الات موسيقية+فشار +أجهزة كهربائية +منتجات تنظيف+عازل سيليكون مطاطي+ الات خط إنتاج المواد الغذائية+ عدد9 سيارات(ارقام الهيكل بالكشف المرفق) | D103: =Sheet2!A103 -> CAIU 834751.2 | E103: =Sheet2!H103 -> 8233 | F103: =Sheet2!G103 -> 86 | J103: بضائع مختلفة
... A114: =Sheet2!B114 -> 238630589 | B114: =Sheet2!C114 -> شركة الريادة للتوكيلات الملاحية | C114: =Sheet2!D114 -> عدد 19150 طرد مواد عناية بالشعر والجسم+ ادوات كهربائية (فيوزات)+مواد تشغيل مصنع مواد غذائية (مكونات+مواد تنظيف+ مواد تغليف+ملابس)+ عدد 2 سيارات(ارقام الهيكل بالكشف المرفق) | D114: =Sheet2!A114 -> MRKU 572025.0 | E114: =Sheet2!H114 -> 17868.5 | F114: =Sheet2!G114 -> 86 | J114: بضائع مختلفة
A115: =Sheet2!B115 -> 238630589 | B115: =Sheet2!C115 -> شركة الريادة للتوكيلات الملاحية | C115: =Sheet2!D115 -> عدد 19150 طرد مواد عناية بالشعر والجسم+ ادوات كهربائية (فيوزات)+مواد تشغيل مصنع مواد غذائية (مكونات+مواد تنظيف+ مواد تغليف+ملابس)+ عدد 2 سيارات(ارقام الهيكل بالكشف المرفق) | D115: =Sheet2!A115 -> MRKU 219840.8 | E115: =Sheet2!H115 -> 17868.6 | F115: 86 | J115: بضائع مختلفة
A116: =Sheet2!B116 -> 238820979 | B116: =Sheet2!C116 -> شركة الريادة للتوكيلات الملاحية | C116: =Sheet2!D116 -> عدد 15043طرد مواد تنظيف+مدفأة كهربائية+حزمة وحدة سطح+مكيف هواء +مواد عناية بالشعر والجسم+ مواد منزلية لاستعمال مرة واحدة+آلة خط انتاج مواد غذائية+عناصر أجهزة منزلية+ عدد9سيارات(أرقام الهياكل بالكشف) | D116: =Sheet2!A116 -> HASU 140368.7 | E116: =Sheet2!H116 -> 11037.65 | F116: =Sheet2!G116 -> 86 | J116: بضائع مختلفة
A117: =Sheet2!B117 -> 238820979 | B117: =Sheet2!C117 -> شركة الريادة للتوكيلات الملاحية | C117: =Sheet2!D117 -> عدد 15043طرد مواد تنظيف+مدفأة كهربائية+حزمة وحدة سطح+مكيف هواء +مواد عناية بالشعر والجسم+ مواد منزلية لاستعمال مرة واحدة+آلة خط انتاج مواد غذائية+عناصر أجهزة منزلية+ عدد9سيارات(أرقام الهياكل بالكشف) | D117: =Sheet2!A117 -> GESU 678428.6 | E117: =Sheet2!H117 -> 11037.65 | F117: =Sheet2!G117 -> 86 | J117: بضائع مختلفة
A118: =Sheet2!B118 -> 238820979 | B118: =Sheet2!C118 -> شركة الريادة للتوكيلات الملاحية | C118: =Sheet2!D118 -> عدد 15043طرد مواد تنظيف+مدفأة كهربائية+حزمة وحدة سطح+مكيف هواء +مواد عناية بالشعر والجسم+ مواد منزلية لاستعمال مرة واحدة+آلة خط انتاج مواد غذائية+عناصر أجهزة منزلية+ عدد9سيارات(أرقام الهياكل بالكشف) | D118: =Sheet2!A118 -> MRKU 636901.0 | E118: =Sheet2!H118 -> 11037.65 | F118: =Sheet2!G118 -> 86 | J118: بضائع مختلفة
...

Sheet Sheet4
A1: A
A2: ابواب ونوافذ
A3: اجبان ومشتقاتها
A4: اجهزة الاكترونية وملحقاتها
A5: اجهزة حاسوب وملحقاتها
A6: اجهزة كهربائية منزلية
A7: اخشاب
A8: ادوات مكتبية وقرطاسية
A9: ادوات منزلية واثاث
A10: اسفنج
A11: اسماك مجمدة
A12: اسمده وتربة زراعية
... A87: نضائد
